<?xml version="1.0" ?>
<robot name="Robot" xmlns:xacro="http://www.ros.org/wiki/xacro">

<xacro:include filename="$(find Robot_description)/urdf/materials.xacro" />
<xacro:include filename="$(find Robot_description)/urdf/Robot.trans" />
<xacro:include filename="$(find Robot_description)/urdf/Robot.gazebo" />
<link name="base_link">
  <inertial>
    <origin xyz="0.0 0.0 0.0" rpy="0 0 0"/>
    <mass value="0.0"/>
    <inertia ixx="0.0" iyy="0.0" izz="0.0" ixy="0.0" iyz="0.0" ixz="0.0"/>
  </inertial>
  <visual>
    <origin xyz="0 0 0" rpy="0 0 0"/>
    <geometry>
      <mesh filename="package://Robot_description/meshes/base_link.stl" scale="0.001 0.001 0.001"/>
    </geometry>
    <material name="silver"/>
  </visual>
  <collision>
    <origin xyz="0 0 0" rpy="0 0 0"/>
    <geometry>
      <mesh filename="package://Robot_description/meshes/base_link.stl" scale="0.001 0.001 0.001"/>
    </geometry>
  </collision>
</link>

<link name="placa_base_1">
  <inertial>
    <origin xyz="0.40877638686219 -1.4600099364657049 -0.6525991128809477" rpy="0 0 0"/>
    <mass value="375.4086793589621"/>
    <inertia ixx="38.020673" iyy="20.791186" izz="56.844586" ixy="-8e-06" iyz="-0.118171" ixz="-0.0"/>
  </inertial>
  <visual>
    <origin xyz="0.011211 -2.022818 -0.91961" rpy="0 0 0"/>
    <geometry>
      <mesh filename="package://Robot_description/meshes/placa_base_1.stl" scale="0.001 0.001 0.001"/>
    </geometry>
    <material name="silver"/>
  </visual>
  <collision>
    <origin xyz="0.011211 -2.022818 -0.91961" rpy="0 0 0"/>
    <geometry>
      <mesh filename="package://Robot_description/meshes/placa_base_1.stl" scale="0.001 0.001 0.001"/>
    </geometry>
  </collision>
</link>

<link name="base_r_1">
  <inertial>
    <origin xyz="-0.07435754686676044 -0.0004390727397289851 0.1163853188916053" rpy="0 0 0"/>
    <mass value="570.670009527453"/>
    <inertia ixx="15.007732" iyy="29.800288" izz="35.945755" ixy="-0.008386" iyz="-0.049965" ixz="0.974627"/>
  </inertial>
  <visual>
    <origin xyz="-0.397565 -0.568456 -0.317359" rpy="0 0 0"/>
    <geometry>
      <mesh filename="package://Robot_description/meshes/base_r_1.stl" scale="0.001 0.001 0.001"/>
    </geometry>
    <material name="silver"/>
  </visual>
  <collision>
    <origin xyz="-0.397565 -0.568456 -0.317359" rpy="0 0 0"/>
    <geometry>
      <mesh filename="package://Robot_description/meshes/base_r_1.stl" scale="0.001 0.001 0.001"/>
    </geometry>
  </collision>
</link>

<link name="s_axis_1">
  <inertial>
    <origin xyz="0.2465402833824955 -0.04135438603178698 0.20193834883312112" rpy="0 0 0"/>
    <mass value="704.6084530701152"/>
    <inertia ixx="48.865557" iyy="116.94191" izz="129.875404" ixy="-10.669964" iyz="3.782292" ixz="12.845024"/>
  </inertial>
  <visual>
    <origin xyz="-0.397565 -0.568456 -0.609359" rpy="0 0 0"/>
    <geometry>
      <mesh filename="package://Robot_description/meshes/s_axis_1.stl" scale="0.001 0.001 0.001"/>
    </geometry>
    <material name="silver"/>
  </visual>
  <collision>
    <origin xyz="-0.397565 -0.568456 -0.609359" rpy="0 0 0"/>
    <geometry>
      <mesh filename="package://Robot_description/meshes/s_axis_1.stl" scale="0.001 0.001 0.001"/>
    </geometry>
  </collision>
</link>

<link name="l_axis_1">
  <inertial>
    <origin xyz="0.027205812442917532 -0.16142313250842483 0.46588585894516765" rpy="0 0 0"/>
    <mass value="552.7971519942739"/>
    <inertia ixx="81.341316" iyy="82.03601" izz="9.751945" ixy="-0.647957" iyz="8.230718" ixz="1.797307"/>
  </inertial>
  <visual>
    <origin xyz="-1.137571 -0.490512 -0.757359" rpy="0 0 0"/>
    <geometry>
      <mesh filename="package://Robot_description/meshes/l_axis_1.stl" scale="0.001 0.001 0.001"/>
    </geometry>
    <material name="silver"/>
  </visual>
  <collision>
    <origin xyz="-1.137571 -0.490512 -0.757359" rpy="0 0 0"/>
    <geometry>
      <mesh filename="package://Robot_description/meshes/l_axis_1.stl" scale="0.001 0.001 0.001"/>
    </geometry>
  </collision>
</link>

<link name="u_axis_1">
  <inertial>
    <origin xyz="0.2916606047917749 0.2143462434100445 0.14928647205424506" rpy="0 0 0"/>
    <mass value="483.4234110989252"/>
    <inertia ixx="14.609702" iyy="57.2139" izz="54.579399" ixy="-6.234945" iyz="-3.416393" ixz="-11.50764"/>
  </inertial>
  <visual>
    <origin xyz="-1.137534 -0.301512 -1.907359" rpy="0 0 0"/>
    <geometry>
      <mesh filename="package://Robot_description/meshes/u_axis_1.stl" scale="0.001 0.001 0.001"/>
    </geometry>
    <material name="silver"/>
  </visual>
  <collision>
    <origin xyz="-1.137534 -0.301512 -1.907359" rpy="0 0 0"/>
    <geometry>
      <mesh filename="package://Robot_description/meshes/u_axis_1.stl" scale="0.001 0.001 0.001"/>
    </geometry>
  </collision>
</link>

<link name="r_axis_1">
  <inertial>
    <origin xyz="0.1685563993211039 -0.07412707539147773 -0.0004901924830997828" rpy="0 0 0"/>
    <mass value="8.899946281447061"/>
    <inertia ixx="0.061278" iyy="0.080342" izz="0.089371" ixy="0.018596" iyz="0.000249" ixz="8.4e-05"/>
  </inertial>
  <visual>
    <origin xyz="-2.166033 -0.568589 -2.157277" rpy="0 0 0"/>
    <geometry>
      <mesh filename="package://Robot_description/meshes/r_axis_1.stl" scale="0.001 0.001 0.001"/>
    </geometry>
    <material name="silver"/>
  </visual>
  <collision>
    <origin xyz="-2.166033 -0.568589 -2.157277" rpy="0 0 0"/>
    <geometry>
      <mesh filename="package://Robot_description/meshes/r_axis_1.stl" scale="0.001 0.001 0.001"/>
    </geometry>
  </collision>
</link>

<link name="b_axis_1">
  <inertial>
    <origin xyz="0.10691585220915689 0.13249813747746259 1.7028415353781412e-05" rpy="0 0 0"/>
    <mass value="45.978906535968754"/>
    <inertia ixx="0.382055" iyy="0.490149" izz="0.580024" ixy="0.018167" iyz="0.000188" ixz="-1.8e-05"/>
  </inertial>
  <visual>
    <origin xyz="-2.362546 -0.399739 -2.157247" rpy="0 0 0"/>
    <geometry>
      <mesh filename="package://Robot_description/meshes/b_axis_1.stl" scale="0.001 0.001 0.001"/>
    </geometry>
    <material name="silver"/>
  </visual>
  <collision>
    <origin xyz="-2.362546 -0.399739 -2.157247" rpy="0 0 0"/>
    <geometry>
      <mesh filename="package://Robot_description/meshes/b_axis_1.stl" scale="0.001 0.001 0.001"/>
    </geometry>
  </collision>
</link>

<link name="t_axis_1">
  <inertial>
    <origin xyz="0.014205681418204996 1.413610909106744e-06 -3.822585659118971e-06" rpy="0 0 0"/>
    <mass value="5.836276011069466"/>
    <inertia ixx="0.025268" iyy="0.013037" izz="0.013093" ixy="1e-06" iyz="0.0" ixz="-4e-06"/>
  </inertial>
  <visual>
    <origin xyz="-2.582537 -0.527255 -2.157192" rpy="0 0 0"/>
    <geometry>
      <mesh filename="package://Robot_description/meshes/t_axis_1.stl" scale="0.001 0.001 0.001"/>
    </geometry>
    <material name="silver"/>
  </visual>
  <collision>
    <origin xyz="-2.582537 -0.527255 -2.157192" rpy="0 0 0"/>
    <geometry>
      <mesh filename="package://Robot_description/meshes/t_axis_1.stl" scale="0.001 0.001 0.001"/>
    </geometry>
  </collision>
</link>

<link name="balancer_2_1">
  <inertial>
    <origin xyz="-1.0071355171291383 -1.141364295073391 -0.48045645693854944" rpy="0 0 0"/>
    <mass value="34.720628844492076"/>
    <inertia ixx="0.366051" iyy="6.432976" izz="6.085232" ixy="0.006621" iyz="-0.001566" ixz="1.432173"/>
  </inertial>
  <visual>
    <origin xyz="-1.412434 -1.519454 -1.498385" rpy="0 0 0"/>
    <geometry>
      <mesh filename="package://Robot_description/meshes/balancer_2_1.stl" scale="0.001 0.001 0.001"/>
    </geometry>
    <material name="silver"/>
  </visual>
  <collision>
    <origin xyz="-1.412434 -1.519454 -1.498385" rpy="0 0 0"/>
    <geometry>
      <mesh filename="package://Robot_description/meshes/balancer_2_1.stl" scale="0.001 0.001 0.001"/>
    </geometry>
  </collision>
</link>

<link name="balancer_1_1">
  <inertial>
    <origin xyz="0.27454396791234575 -1.5743809510766291 -0.7961805409798757" rpy="0 0 0"/>
    <mass value="1052.0941459866974"/>
    <inertia ixx="24.423311" iyy="134.3907" izz="128.357793" ixy="-0.008244" iyz="0.001953" ixz="26.045583"/>
  </inertial>
  <visual>
    <origin xyz="0.078722 -1.952822 -1.863697" rpy="0 0 0"/>
    <geometry>
      <mesh filename="package://Robot_description/meshes/balancer_1_1.stl" scale="0.001 0.001 0.001"/>
    </geometry>
    <material name="silver"/>
  </visual>
  <collision>
    <origin xyz="0.078722 -1.952822 -1.863697" rpy="0 0 0"/>
    <geometry>
      <mesh filename="package://Robot_description/meshes/balancer_1_1.stl" scale="0.001 0.001 0.001"/>
    </geometry>
  </collision>
</link>

<joint name="base_link1" type="prismatic">
  <origin xyz="-0.011211 2.022818 0.91961" rpy="0 0 0"/>
  <parent link="base_link"/>
  <child link="placa_base_1"/>
  <axis xyz="0.0 -1.0 0.0"/>
  <limit upper="-0.01" lower="-1.9" effort="100" velocity="100"/>
</joint>

<joint name="rig1" type="fixed">
  <origin xyz="0.408776 -1.454362 -0.602251" rpy="0 0 0"/>
  <parent link="placa_base_1"/>
  <child link="base_r_1"/>
</joint>

<joint name="link1_link2" type="continuous">
  <origin xyz="0.0 0.0 0.292" rpy="0 0 0"/>
  <parent link="base_r_1"/>
  <child link="s_axis_1"/>
  <axis xyz="0.0 0.0 1.0"/>
</joint>

<joint name="link2_link3" type="revolute">
  <origin xyz="0.740006 -0.077944 0.148" rpy="0 0 0"/>
  <parent link="s_axis_1"/>
  <child link="l_axis_1"/>
  <axis xyz="7.5e-05 -1.0 0.0"/>
  <limit upper="0.610865" lower="-1.22173" effort="100" velocity="100"/>
</joint>

<joint name="link3_link4" type="continuous">
  <origin xyz="-3.7e-05 -0.189 1.15" rpy="0 0 0"/>
  <parent link="l_axis_1"/>
  <child link="u_axis_1"/>
  <axis xyz="-7.5e-05 1.0 -0.0"/>
</joint>

<joint name="link4_link5" type="continuous">
  <origin xyz="1.028499 0.267077 0.249918" rpy="0 0 0"/>
  <parent link="u_axis_1"/>
  <child link="r_axis_1"/>
  <axis xyz="1.0 7.5e-05 -8e-05"/>
</joint>

<joint name="link5_link6" type="revolute">
  <origin xyz="0.196513 -0.16885 -3e-05" rpy="0 0 0"/>
  <parent link="r_axis_1"/>
  <child link="b_axis_1"/>
  <axis xyz="7.5e-05 -1.0 -8.2e-05"/>
  <limit upper="2.094395" lower="-2.094395" effort="100" velocity="100"/>
</joint>

<joint name="link6_link7" type="continuous">
  <origin xyz="0.219991 0.127516 -5.5e-05" rpy="0 0 0"/>
  <parent link="b_axis_1"/>
  <child link="t_axis_1"/>
  <axis xyz="1.0 7.5e-05 -0.000297"/>
</joint>

<joint name="rig2" type="fixed">
  <origin xyz="1.014869 0.950998 0.889026" rpy="0 0 0"/>
  <parent link="s_axis_1"/>
  <child link="balancer_2_1"/>
</joint>

<joint name="rig3" type="fixed">
  <origin xyz="-1.491156 0.433368 0.365312" rpy="0 0 0"/>
  <parent link="balancer_2_1"/>
  <child link="balancer_1_1"/>
</joint>

</robot>
